> Данный ман - это скорее поток сознания, нежели что-то сильно структурированное, потому что расписать последовательно оказалось непросто. Так что его надо прочитать полностью, так сказать, разом загрузить в голову и тогда картинка сложится

Если код, в котором произошло исключение, находится в блоке try, то CLR пытается найти ближайший подходящий catch. Если catch не найден, программа вылетает с ошибкой. Если найден, то выполняется этот catch, потом finally (если он есть), а потом программа идет дальше как обычно.

Вот несколько примеров (часть примеров по сути слишком искусственные и так никогда не пишут, но они представляют чисто экспериментальный интерес, "а что будет, если извернуться и написать вот так"):

# Блока catch нет вообще

► Первый бессмысленный с практической точки зрения пример, в котором нет catch:

```c#
Func<int, int, float> divide = (x, y) => x / y;
            
try
{
    var z = divide(5, 0);
}
finally
{
    Console.WriteLine("finally отработал");
}
```

При возникновении исключения в таком случае программа просто вылетает. Если исключение не возникнет, тогда finally выполнится.

На всякий случай отмечу - переменная z в блоке finally не видна

► Второй бессмысленный на практике пример без catch:

```c#
class ExceptionsDemo
{
	public static void Divide(int x, int y)
    {
        var z = x / y;  // <-- опасное место
        Console.WriteLine("Метод Divide завершил работу");
    }

    public static void Execute(int x, int y)
    {
        try  // <-- try без catch - деньги на ветер
        {
            Divide(x, y);
        }
        finally 
        {
            Console.WriteLine("finally в методе Execute");
        }
        Console.WriteLine("Метод Execute завершил работу");
    }
}
```

```c#
ExceptionsDemo.Execute(5, 0);  // Вылет программы
```

В этом примере исключение возникнет в методе Divide. Хотя строчка `var z = x / y`, которая непосредственно приводит к ошибке, не обрамлена в try, *CLR пойдет вверх по стеку в поисках того, кто бы мог обработать эту ошибку*. Поскольку в методе Execute тоже нет catch, программа опять вылетит.

Таким образом, писать try вообще без catch бессмысленно, потому что в случае возникновения исключения программа просто вылетает и finally не выполняется

> UPD. Вообще-то в принципе такой смысл есть - на try-finally без catch построен сахар using. Но если разговор именно о попытке *обработать* ошибку, тогда да, смысла нет

# Блок catch есть

► Чуть более адекватный пример. Здесь опасная строчка обрамлена в try и имеется finally, но "своего" catch нету - а "чужой" находится выше по стеку. Пример показывает, как CLR поднимается по стеку в поисках catch, а после того как его находит, начинает обработку с ближайшего к месту исключения блока (в данном случае это finally в Divide). На деле же я думаю пример все равно слишком синтетический, потому что нет смысла писать try и не приделывать к нему тут же catch, но тем не менее, в экспериментальных целях:

```c#
class ExceptionsDemo
{
    public static void Divide(int x, int y)
    {
        try
        {
            var z = x / y;
        }  // <-- свой catch отсутствует, но есть catch выше по стеку
        finally
        {
            Console.WriteLine("finally в методе Divide");
        }
        Console.WriteLine("Метод Divide завершил работу");
    }

    public static void Execute(int x, int y)
    {
        try
        {
            Divide(x, y);
        }
        catch  // <-- вот он
        {
            Console.WriteLine("catch в методе Execute");
        }
        finally
        {
            Console.WriteLine("finally в методе Execute");
        }
        Console.WriteLine("Метод Execute завершил работу");
    }
}
```

Провоцируем ошибку:

```c#
ExceptionsDemo.Execute(5, 0);
// finally в методе Divide
// catch в методе Execute
// finally в методе Execute
// Метод Execute завершил работу
```

Видно, что хотя catch, который обрабатывает ошибку, относится не к тому try, где ошибка возникла, все равно работа начинается от точки, ближайшей к месту ошибки - то есть из блока finally метода Divide.

Передаем корректные данные:

```c#
ExceptionsDemo.Execute(5, 1);
// finally в методе Divide
// Метод Divide завершил работу
// finally в методе Execute
// Метод Execute завершил работу
```

Когда исключение не возникает, блоки finally все равно выполняются



# Работа с блоком catch

► В блоке catch можно не указывать тип исключения, тогда он будет реагировать на все типы :

```c#
try 
{
    
}
catch
{
    
}
```

► Чтобы получить доступ к объекту возникшего исключения, нужно указать переменную:

```c#
Func<int, int, float> divide = (x, y) => x / y;

try
{
    var z = divide(5, 0);
}
catch (Exception ex)  // <-- в ex окажется объект исключения
{
    Console.WriteLine(ex.GetType());  // System.DivideByZeroException
}
```

Если объект не нужен, то переменную можно не указывать

► Более специфичные типы нужно указывать раньше общих, иначе до них дело никогда не дойдет:

```c#
try
{
    var z = divide(5, 0);
}
catch (Exception)
{
    Console.WriteLine("Какая-то ошибка");
}
catch (DivideByZeroException ex)  // никогда не выполнится, надо поменять блоки местами
{
    Console.WriteLine("Деление на ноль");
}
```

> Такой вариант даже не скомпилируется, будет ошибка: "A previous catch clause already catches all exceptions of this or of a super type ('Exception')"

► Можно указать дополнительное условие, при котором catch должен срабатывать:

```c#
try
{
    throw new WebException("Connectin failure", WebExceptionStatus.ConnectFailure);
}
catch (WebException ex) when (ex.Status == WebExceptionStatus.ConnectFailure)
{
    Console.WriteLine("Обработка ошибки соединения");
}
catch (WebException ex) when (ex.Status == WebExceptionStatus.RequestCanceled)
{
    Console.WriteLine("Обработка отмены запроса");
}
```

В данном случае мы обращаемся к объекту исключения и задаем дополнительное условие по его полю и таким образом оформляем обработку в виде нескольких блоков catch вместо того, чтобы писать if'ы

# Вложенные исключения

У всех исключений есть свойство `InnerException`:

```c#
try
{
    int x = 5, y = 0;
    var z = x / y;
}
catch (DivideByZeroException ex)
{
    var inner = ex.InnerException;  // null
}
```

В данном случае оно null.

Как оно формируется и зачем нужно? Формируется например вот так:

```c#
public static void Divide(int x, int y)
{
    try
    {
        var z = x / y;
    }
    catch (DivideByZeroException ex)
    {
        throw new ArgumentException("y равен 0", ex);  // <--
    }
}
```

То есть просто при создании объекта исключения кладем в его свойство InnerException какой-нибудь другой объект исключения. Таким образом формируется матрешка исключений и это например дает понимание, какова была цепочка исключений, приведшая к текущему моменту и позволяет извлечь из них какую-нибудь информацию



# Повторный выброс исключения

Можно повторно выбросить то же самое исключение с помощью команды `throw`. Это обычно полезно для логирования - даже если ошибку исправить не удается, то полезно записать куда-то факт ее возникновения и сопутствующую информацию:

```c#
static void Main(string[] args)
{
    try
    {
        int x = 5, y = 0;
        var z = x / y;
    }
    catch (Exception ex)
    {
        Console.WriteLine("Залогировали факт ошибки");
        // Но что с ней делать, не знаем, поэтому генерируем ее снова
        // Пусть вызывающий код думает
        throw;  // <--
    }
    finally
    {
        Console.WriteLine("от finally не убежать");  // не выведется
    }
    Console.WriteLine("Завершение main");  // не выведется
}
```

При этом, как видно, finally не выполняется, потому что повторно выброшенное исключение уже никем не поймано. 

Будучи пойманным одним из блоков catch, исключение остальными уже не ловится. Так что например вот такая попытка обработать повторно выброшенное исключение не сработает:

```c#
static void Main(string[] args)
{
    try
    {
        int x = 5, y = 0;
        var z = x / y;
    }
    catch (DivideByZeroException ex)
    {
        Console.WriteLine("Залогировали факт ошибки");
        // Но что с ней делать, не знаем, поэтому генерируем ее снова
        // Пусть вызывающий код думает
        throw;
    }
    catch  // <-- этот catch не ловит повторное исключение
    {
        Console.WriteLine("Ловим второй раз");  // на самом деле не ловим
    }
    finally
    {
        Console.WriteLine("от finally не убежать");  // => не выведется
    }
    Console.WriteLine("Завершение main");  // => не выведется
}

// Output: Залогировали факт ошибки
```

Повторно выброшенные исключения ловятся вверх по стеку:

```c#
class ExceptionsDemo
{
    private static void Divide(int x, int y)
    {
        try
        {
            var z = x / y;
        }
        catch (DivideByZeroException ex)
        {
            throw new ArgumentException("y равен 0", ex);
        }
    }

    public static void Execute(int x, int y)
    {
        try
        {
            Divide(x, y);
        }
        catch (Exception ex)  // <-- повторное поймается вот здесь
        {
            var inner = ex.InnerException;
            Console.WriteLine(inner.Message);
        }
    }
}

static void Main(string[] args)
{
	ExceptionsDemo.Execute(5, 0);
}
```



# finally

Выполнению блока finally может помешать только бесконечный цикл или принудительное завершение процесса. В остальных случаях, если исключение поймано или не произошло вообще, finally выполняется железно:

```c#
static void Main(string[] args)
{
	try
    {
        return;  // <-- перед тем как выйти из функции, finally все равно выполнится
    }
    finally
    {
        Console.WriteLine("от finally не убежать");
    }
    Console.WriteLine("Завершение main");  // не выведется
}

// Output: от finally не убежать
```

```c#
static void Main(string[] args)
{
    try
    {
        throw new Exception();
    }
    catch
    {
        return;
    }
    finally
    {
        Console.WriteLine("от finally не убежать");
    }
    Console.WriteLine("Завершение main");  // не выведется
}

// Output: от finally не убежать
```

```c#
try
{
    try
    {
        throw new ArgumentNullException();
    }
    finally
    {
        Console.WriteLine("inner finally");
    }
}
catch
{
    Console.WriteLine("outter catch");
}
finally
{
    Console.WriteLine("outter finally");
}
```

Выведется inner finaly - outter catch - outter finally. То есть, несмотря на то, что во внутреннем блоке try отсутствует catch, его finally все равно выполнится, потому что исключение отлавливается внешним catch (причем выполнится этот внутренний finally ДО этого catch)



# Резюме

* После `try` должен быть блок `catch` или `finally` (или оба). То есть просто написать try без ничего - нельзя
* Когда возникает исключение, CLR сначала ищет, есть ли *в принципе где-нибудь в стеке вызовов* catch, который может его обработать, а потом начинает обработку с блока, ближайшего к тому try, в котором исключение возникло
* Блок finally выполняется *всегда*, если исключение обработано или не возникло
* Исключение можно выбросить повторно с помощью команды throw